Workbook

Sheet 🗂 CRM База
B1: 📍 ІНФОРМАЦІЯ | J1: 🔍 АНАЛІЗ | Q1: 💼 CRM ПРОДАЖІ
A2: # | B2: НАЗВА ЗАКЛАДУ | C2: АДРЕСА | D2: ТЕЛЕФОН | E2: INSTAGRAM | F2: WEBSITE | G2: 📍 | H2: ⭐ | I2: ВІДГУКІВ | J2: ТИП ЛІДУ | K2: САЙТ | L2: IG | M2: ПРІОРИТ. | N2: ПРИЧИНА | O2: ПІДХІД | P2: ЯКІСТЬ 1–10 | Q2: КОНТАКТ | R2: ПЕРШИЙ КОНТАКТ | S2: СПОСІБ | T2: СТАТУС | U2: НАСТУПНА ДІЯ | V2: ДАТА ДІЇ | W2: КОМЕНТАР
A3: 1 | B3: Cacao | C3: вул. проспект Червоної Калини, 68, Львів | F3: https://www.instagram.com/cacao.lviv?igsh=YzFyMm5yaDl0ZnE= | G3: 📍 | J3: 🌐 Є сайт | K3: ✅ | L3: ❌ | M3: 🟡 B | T3: 🟡 Новий
A4: 2 | B4: Celentano | C4: вул. вулиця Тараса Шевченка, 17, Львів | D4: +38068 055 1717 | F4: https://www.velyka-brytaniya.celentano.delivery/ | G4: 📍 | J4: 🌐 Є сайт | K4: ✅ | L4: ❌ | M4: 🟡 B | T4: 🟡 Новий | Y4: 🟡 Новий | Z4: =COUNTIF(T$3:T$977,"🟡 Новий")
A5: 3 | B5: Cheese Bakery | C5: Львів | F5: https://cheesebakery.com.ua/ | G5: 📍 | J5: 🌐 Є сайт | K5: ✅ | L5: ❌ | M5: 🟡 B | T5: 🟡 Новий | Y5: 🔵 Домовляємось | Z5: =COUNTIF(T$3:T$977,"🔵 Домовляємось")
A6: 4 | B6: Coffee Lab | C6: вул. Стрийська вулиця, 76, Львів | D6: +380673444423 | F6: https://www.facebook.com/coffeelablviv | G6: 📍 | J6: 🌐 Є сайт | K6: ✅ | L6: ❌ | M6: 🟡 B | T6: 🟡 Новий | Y6: 🟣 Презентація | Z6: =COUNTIF(T$3:T$977,"🟣 Презентація")
A7: 5 | B7: Coffee Power | C7: Львів | F7: https://www.instagram.com/coffeepower__/ | G7: 📍 | J7: 🌐 Є сайт | K7: ✅ | L7: ❌ | M7: 🟡 B | T7: 🟡 Новий | Y7: 🟠 Думає | Z7: =COUNTIF(T$3:T$977,"🟠 Думає")
A8: 6 | B8: Jam Cafe | C8: Львів | D8: +380678652323 | F8: inst: @jam.cafe_lv | G8: 📍 | J8: 🌐 Є сайт | K8: ✅ | L8: ❌ | M8: 🟡 B | T8: 🟡 Новий | Y8: 🟢 Продано | Z8: =COUNTIF(T$3:T$977,"🟢 Продано")
A9: 7 | B9: KREDENS | C9: Львів | F9: https://www.kredens.com.ua | G9: 📍 | J9: 🌐 Є сайт | K9: ✅ | L9: ❌ | M9: 🟡 B | T9: 🟡 Новий | Y9: 🔴 Відмовився | Z9: =COUNTIF(T$3:T$977,"🔴 Відмовився")
A10: 8 | B10: Kredens Cafe | C10: Львів | E10: @kredenscafe | F10: https://www.kredens.com.ua/ | G10: 📍 | J10: 🌐 Є сайт | K10: ✅ | L10: ✅ | M10: 🟡 B | T10: 🟡 Новий
A11: 9 | B11: La П'єц - | C11: Львів | D11: +380 97 440 4060 | F11: http://pizza-lapiec.com.ua | G11: 📍 | J11: 🌐 Є сайт | K11: ✅ | L11: ❌ | M11: 🟡 B | T11: 🟡 Новий
A12: 10 | B12: La П'єц - піца на дровах | C12: Львів | D12: +380 97 440 4060 | F12: http://pizza-lapiec.com.ua | G12: 📍 | J12: 🌐 Є сайт | K12: ✅ | L12: ❌ | M12: 🟡 B | T12: 🟡 Новий
A13: 11 | B13: Le Petit Café Lviv | C13: вул. Катедральна площа, 5, Львів | D13: +380675331513 | F13: http://bit.ly/LePetitCaf%C3%A9Lviv-Menu | G13: 📍 | J13: 🌐 Є сайт | K13: ✅ | L13: ❌ | M13: 🟡 B | T13: 🟡 Новий
A14: 12 | B14: Libraria | C14: вул. вулиця Лесі Українки, 14, Львів | D14: +380 67 726 4924 | F14: https://libraria.com.ua/ | G14: 📍 | J14: 🌐 Є сайт | K14: ✅ | L14: ❌ | M14: 🟡 B | T14: 🟡 Новий
A15: 13 | B15: Locals b&bistro | C15: вул. вулиця Тараса Шевченка, 21, Львів | D15: 0970744686 | F15: https://www.instagram.com/locals_bistro?igsh=MW12c3EzOGxoOXZ1ag== | G15: 📍 | J15: 🌐 Є сайт | K15: ✅ | L15: ❌ | M15: 🟡 B | T15: 🟡 Новий
A16: 14 | B16: Lviv Croissants | C16: Львів | D16: +380 67 875 3506 | E16: @LvivCroissants | F16: https://www.lviv-croissants.com/ | G16: 📍 | J16: 🌐 Є сайт | K16: ✅ | L16: ✅ | M16: 🟡 B | T16: 🟡 Новий
A17: 15 | B17: MA Pizza | C17: вул. Китайська вулиця, 10, Львів | D17: +38 097 18 306 18 | F17: https://mapizza.com.ua/ | G17: 📍 | J17: 🌐 Є сайт | K17: ✅ | L17: ❌ | M17: 🟡 B | T17: 🟡 Новий
A18: 16 | B18: My Kava | C18: вул. Пекарська вулиця, 26, Львів | D18: +380686931842 | F18: https://mykava.ua/ | G18: 📍 | J18: 🌐 Є сайт | K18: ✅ | L18: ❌ | M18: 🟡 B | T18: 🟡 Новий
A19: 17 | B19: People Place Bar | C19: вул. Катедральна площа, 6, Львів | D19: +380322975674 | F19: https://peopleplacebar.choiceqr.com/a/QUYb-SDIt | G19: 📍 | J19: 🌐 Є сайт | K19: ✅ | L19: ❌ | M19: 🟡 B | T19: 🟡 Новий
A20: 18 | B20: Rockfellow | C20: Львів | F20: https://rockfellow.com.ua/ | G20: 📍 | J20: 🌐 Є сайт | K20: ✅ | L20: ❌ | M20: 🟡 B | T20: 🟡 Новий
A21: 19 | B21: SHOco. | C21: Львів | F21: https://shoco-zwin.choiceqr.com/ | G21: 📍 | J21: 🌐 Є сайт | K21: ✅ | L21: ❌ | M21: 🟡 B | T21: 🟡 Новий
A22: 20 | B22: Saturdays Coffee | C22: Львів | F22: https://www.instagram.com/saturdayscoffeelviv | G22: 📍 | J22: 🌐 Є сайт | K22: ✅ | L22: ❌ | M22: 🟡 B | T22: 🟡 Новий
A23: 21 | B23: Sowá Cafe | C23: Львів | D23: +380 98 634 9046 | F23: https://www.facebook.com/sowalviv | G23: 📍 | J23: 🌐 Є сайт | K23: ✅ | L23: ❌ | M23: 🟡 B | T23: 🟡 Новий
A24: 22 | B24: Tea Room | C24: вул. Піша вулиця, 2, Львів | F24: https://instagram.com/tea_room_lviv?igshid=1jmkx12q4fs5w | G24: 📍 | J24: 🌐 Є сайт | K24: ✅ | L24: ❌ | M24: 🟡 B | T24: 🟡 Новий
A25: 23 | B25: The Wave Project | C25: Львів | F25: https://instagram.com/thewaveproject.ua?utm_medium=copy_link | G25: 📍 | J25: 🌐 Є сайт | K25: ✅ | L25: ❌ | M25: 🟡 B | T25: 🟡 Новий
A26: 24 | B26: Totem Cafe | C26: Львів | D26: +380 97 034 8280 | F26: https://totem-cafe-cafe.business.site/ | G26: 📍 | J26: 🌐 Є сайт | K26: ✅ | L26: ❌ | M26: 🟡 B | T26: 🟡 Новий
A27: 25 | B27: Інтемпо | C27: вул. Городоцька вулиця, 110, Львів | F27: https://sezony.com.ua/ | G27: 📍 | J27: 🌐 Є сайт | K27: ✅ | L27: ❌ | M27: 🟡 B | T27: 🟡 Новий
A28: 26 | B28: Інші | C28: Львів | D28: +380683023042 | F28: https://expz.menu/a66dff7e-d106-4c62-970a-4ce7fe12d1ec | G28: 📍 | J28: 🌐 Є сайт | K28: ✅ | L28: ❌ | M28: 🟡 B | T28: 🟡 Новий
A29: 27 | B29: Або кава | C29: вул. Промислова вулиця, 27, Львів | D29: +380 68 526 5616 | E29: @tsikava.foodandcoffee | F29: https://tsikava.com/ | G29: 📍 | J29: 🌐 Є сайт | K29: ✅ | L29: ✅ | M29: 🟡 B | T29: 🟡 Новий
A30: 28 | B30: Альтернативна Кава | C30: Львів | E30: @alterkava | F30: https://altkava.com.ua/ | G30: 📍 | J30: 🌐 Є сайт | K30: ✅ | L30: ✅ | M30: 🟡 B | T30: 🟡 Новий
A31: 29 | B31: Антикафе "Come In" | C31: Львів | D31: +380 63 848 4891 | F31: https://comein.lviv.ua/ | G31: 📍 | J31: 🌐 Є сайт | K31: ✅ | L31: ❌ | M31: 🟡 B | T31: 🟡 Новий
A32: 30 | B32: Бiла Кава | C32: вул. вулиця Івана Тиктора, 4, Львів | D32: +380 97 064 9676 | F32: https://www.bilakava.com/ | G32: 📍 | J32: 🌐 Є сайт | K32: ✅ | L32: ❌ | M32: 🟡 B | T32: 🟡 Новий
A33: 31 | B33: Біля Діани на Ринку | C33: Львів | D33: +380 50 378 6038 | F33: http://www.fest.lviv.ua/uk/restaurants/diananarynku | G33: 📍 | J33: 🌐 Є сайт | K33: ✅ | L33: ❌ | M33: 🟡 B | T33: 🟡 Новий
A34: 32 | B34: Вишиванка | C34: Львів | F34: http://vyshyvanka.lviv.ua/ | G34: 📍 | J34: 🌐 Є сайт | K34: ✅ | L34: ❌ | M34: 🟡 B | T34: 🟡 Новий
A35: 33 | B35: Вок Піца | C35: Львів | D35: +380 63 174 7575 | F35: https://wokpizza.lviv.ua/ | G35: 📍 | J35: 🌐 Є сайт | K35: ✅ | L35: ❌ | M35: 🟡 B | T35: 🟡 Новий
A36: 34 | B36: Вірменка | C36: Львів | D36: +380 67 278 1608 | F36: http://www.virmenka.akurat.com.ua/ | G36: 📍 | J36: 🌐 Є сайт | K36: ✅ | L36: ❌ | M36: 🟡 B | T36: 🟡 Новий
A37: 35 | B37: Ен Салада | C37: Львів | D37: +380 96 857 3085 | F37: https://ensalada.com.ua/ | G37: 📍 | J37: 🌐 Є сайт | K37: ✅ | L37: ❌ | M37: 🟡 B | T37: 🟡 Новий
A38: 36 | B38: Зашкварка | C38: вул. Пекарська вулиця, 2, Львів | D38: 0 (93) 381 87 03 | F38: https://zashkvarka.choiceqr.com/menu | G38: 📍 | J38: 🌐 Є сайт | K38: ✅ | L38: ❌ | M38: 🟡 B | T38: 🟡 Новий
A39: 37 | B39: Зелені пагорби | C39: Львів | F39: https://lioncastlehotel.com/restoran/ | G39: 📍 | J39: 🌐 Є сайт | K39: ✅ | L39: ❌ | M39: 🟡 B | T39: 🟡 Новий
A40: 38 | B40: Кет Кафе | C40: вул. площа Генерала Петра Григоренка, 1а, Львів | D40: +380 67 804 4780 | F40: https://catcafe.com.ua/ | G40: 📍 | J40: 🌐 Є сайт | K40: ✅ | L40: ❌ | M40: 🟡 B | T40: 🟡 Новий
...

Sheet 💰 Угоди
A1: 💰 ТРЕКЕР УГОД — LIBERTY CRM
A2: ID КЛІЄНТА | B2: КАВ'ЯРНЯ | C2: СТАТУС УГОДИ | D2: СУМА, грн | E2: ДАТА УГОДИ | F2: НОТАТКА
B3: =IF(A3="","",IFERROR(INDEX('🗂 CRM База'!$B$3:$B$977,A3),"❓ ID не знайдено")) | H3: Домовились на зустріч | I3: =COUNTIF($C$3:$C$52,H3)
B4: =IF(A4="","",IFERROR(INDEX('🗂 CRM База'!$B$3:$B$977,A4),"❓ ID не знайдено")) | H4: Зустрілись | I4: =COUNTIF($C$3:$C$52,H4)
B5: =IF(A5="","",IFERROR(INDEX('🗂 CRM База'!$B$3:$B$977,A5),"❓ ID не знайдено")) | H5: Очікуємо відповіді | I5: =COUNTIF($C$3:$C$52,H5)
B6: =IF(A6="","",IFERROR(INDEX('🗂 CRM База'!$B$3:$B$977,A6),"❓ ID не знайдено")) | H6: Презентація | I6: =COUNTIF($C$3:$C$52,H6)
B7: =IF(A7="","",IFERROR(INDEX('🗂 CRM База'!$B$3:$B$977,A7),"❓ ID не знайдено")) | H7: Оплачено ✅ | I7: =COUNTIF($C$3:$C$52,H7)
B8: =IF(A8="","",IFERROR(INDEX('🗂 CRM База'!$B$3:$B$977,A8),"❓ ID не знайдено")) | H8: Скасовано ❌ | I8: =COUNTIF($C$3:$C$52,H8)
B9: =IF(A9="","",IFERROR(INDEX('🗂 CRM База'!$B$3:$B$977,A9),"❓ ID не знайдено"))
B10: =IF(A10="","",IFERROR(INDEX('🗂 CRM База'!$B$3:$B$977,A10),"❓ ID не знайдено"))
B11: =IF(A11="","",IFERROR(INDEX('🗂 CRM База'!$B$3:$B$977,A11),"❓ ID не знайдено"))
B12: =IF(A12="","",IFERROR(INDEX('🗂 CRM База'!$B$3:$B$977,A12),"❓ ID не знайдено"))
B13: =IF(A13="","",IFERROR(INDEX('🗂 CRM База'!$B$3:$B$977,A13),"❓ ID не знайдено"))
B14: =IF(A14="","",IFERROR(INDEX('🗂 CRM База'!$B$3:$B$977,A14),"❓ ID не знайдено"))
B15: =IF(A15="","",IFERROR(INDEX('🗂 CRM База'!$B$3:$B$977,A15),"❓ ID не знайдено"))
B16: =IF(A16="","",IFERROR(INDEX('🗂 CRM База'!$B$3:$B$977,A16),"❓ ID не знайдено"))
B17: =IF(A17="","",IFERROR(INDEX('🗂 CRM База'!$B$3:$B$977,A17),"❓ ID не знайдено"))
B18: =IF(A18="","",IFERROR(INDEX('🗂 CRM База'!$B$3:$B$977,A18),"❓ ID не знайдено"))
B19: =IF(A19="","",IFERROR(INDEX('🗂 CRM База'!$B$3:$B$977,A19),"❓ ID не знайдено"))
B20: =IF(A20="","",IFERROR(INDEX('🗂 CRM База'!$B$3:$B$977,A20),"❓ ID не знайдено"))
... B52: =IF(A52="","",IFERROR(INDEX('🗂 CRM База'!$B$3:$B$977,A52),"❓ ID не знайдено"))
D53: Всього угод | E53: Оплачено | F53: Конверсія %
A54: 💵 ЗАГАЛЬНА ВИРУЧКА | C54: =SUMIF(C3:C52,"Оплачено ✅",D3:D52) | D54: =COUNTA(A3:A52) | E54: =COUNTIF(C3:C52,"Оплачено ✅") | F54: =IFERROR(COUNTIF(C3:C52,"Оплачено ✅")/COUNTA(A3:A52)*100,0)

Sheet 📖 Легенда
B1: 📖 ЛЕГЕНДА — СТАТУСИ, ПРИЧИНИ, СКРИПТИ
B2: СТАТУСИ CRM
B3: 🟡 Новий | C3: Перший контакт ще не відбувся
B4: 🔵 Домовляємось | C4: Ведемо перемовини, обговорюємо деталі
B5: 🟣 Презентація | C5: Показали демо — liberty-cafe.onrender.com
B6: 🟠 Думає | C6: Клієнт розглядає пропозицію
B7: 🟢 Продано | C7: ✅ Угода закрита, отримали оплату
B8: 🔴 Відмовився | C8: Не зацікавлений — повернись через 3 місяці
B10: ТИП ЛІДУ → СТРАТЕГІЯ
B11: 🔥 Без сайту | C11: Дзвінок або візит. «Знайшов вас в Google — немає сайту, є 5 хв?»
B12: 📸 Instagram тільки | C12: Direct: «Ваші фото — вогонь! Але Google вас не показує. Маю рішення»
B13: 🌐 Є сайт | C13: Відкрий їх сайт на телефоні при власнику. Мовчки. Нехай самі побачать.
B15: СКРИПТ ПЕРШОГО КОНТАКТУ
B16: Крок 1 → | C16: «Добрий день! Я [ім'я], роблю сайти для кав'ярень у Львові»
B17: Крок 2 → | C17: «Знайшов вас — помітив що [причина]. Хочу показати щось за 3 хв»
B18: Крок 3 → | C18: Показуєш liberty-cafe.onrender.com на своєму телефоні
B19: Крок 4 → | C19: «Це я зроблю для вас за [ціна] і [строк]»
B21: ВІДПОВІДІ НА ЗАПЕРЕЧЕННЯ
B22: «Вже є Instagram» | C22: «Instagram не індексується Google. Людина що шукає 'кав'ярня Львів' — вас не знайде»
B23: «Немає часу» | C23: «Від вас — 30 хв на початку. Далі ви самі оновлюєте меню за 2 кліки»
B24: «Дорого» | C24: «Скільки ви заробляєте з одного столика? Сайт окупається після першого нового клієнта»
B25: «Подумаю» | C25: «Добре! Залишу вам демо прямо зараз — покажете партнеру?» → пиши через 3 дні
